Workbook

Sheet ISN
A2: Voucheo de Impuesto Sobre Nóminas 2026
A3: MES | B3: TIPO | C3: TIPO2 | D3: ESTADO | E3: TOTAL DE REMUNERACONES | F3: TASA | G3: IMPUESTO CAUSADO | H3: ACTUALIZACIONES | I3: RECARGOS | J3: GASTOS DE EJECUCIÓN | K3: RETENCIONES ISN | L3: ISN A FAVOR | M3: CANTIDAD A PAGAR | N3: CANTIDAD PAGADA | O3: CANTIDAD A FAVOR | Q3: NUMERO DE COLABORADORES | R3: FECHA DE PRESENTACIÓN | S3: FOLIO | T3: REFERENCIA PAGO: | U3: FECHA DE PAGO EN BANCO | V3: INSTITUCIÓN BANCARIA | W3: No. DE OPERACIÓN BANCO | X3: FACTURADO | Y3: UUID
A5: ENERO | G5: =ROUND(E5*F5,0) -> 0 | H5: 0 | I5: 0 | J5: 0 | K5: 0 | L5: 0 | M5: =G5+H5+I5+J5-K5-L5 -> 0 | N5: 0 | O5: 0
A6: ENERO | G6: =E6*F6 -> 0 | H6: 0 | I6: 0 | J6: 0 | K6: 0 | L6: 0 | M6: =G6+H6+I6+J6-K6-L6 -> 0 | O6: =H6+I6+J6+K6-L6-M6 -> 0
A7: ENERO | G7: =E7*F7 -> 0 | H7: 0 | I7: 0 | J7: 0 | K7: 0 | L7: 0 | M7: =G7+H7+I7+J7-K7-L7 -> 0 | O7: =H7+I7+J7+K7-L7-M7 -> 0
A8: ENERO | G8: =E8*F8 -> 0 | H8: 0 | I8: 0 | J8: 0 | K8: 0 | L8: 0 | M8: =G8+H8+I8+J8-K8-L8 -> 0 | O8: =H8+I8+J8+K8-L8-M8 -> 0
A9: ENERO | G9: =E9*F9 -> 0 | H9: 0 | I9: 0 | J9: 0 | K9: 0 | L9: 0 | M9: =G9+H9+I9+J9-K9-L9 -> 0 | O9: =H9+I9+J9+K9-L9-M9 -> 0
A11: FEBRERO | G11: =ROUND(E11*F11,0) -> 0 | H11: 0 | I11: 0 | J11: 0 | K11: 0 | L11: 0 | M11: =G11+H11+I11+J11-K11-L11 -> 0 | N11: 0 | O11: 0
A12: FEBRERO | G12: =E12*F12 -> 0 | H12: 0 | I12: 0 | J12: 0 | K12: 0 | L12: 0 | M12: =G12+H12+I12+J12-K12-L12 -> 0 | O12: =H12+I12+J12+K12-L12-M12 -> 0
A13: FEBRERO | G13: =E13*F13 -> 0 | H13: 0 | I13: 0 | J13: 0 | K13: 0 | L13: 0 | M13: =G13+H13+I13+J13-K13-L13 -> 0 | O13: =H13+I13+J13+K13-L13-M13 -> 0
A14: FEBRERO | G14: =E14*F14 -> 0 | H14: 0 | I14: 0 | J14: 0 | K14: 0 | L14: 0 | M14: =G14+H14+I14+J14-K14-L14 -> 0 | O14: =H14+I14+J14+K14-L14-M14 -> 0
A15: FEBRERO | G15: =E15*F15 -> 0 | H15: 0 | I15: 0 | J15: 0 | K15: 0 | L15: 0 | M15: =G15+H15+I15+J15-K15-L15 -> 0 | O15: =H15+I15+J15+K15-L15-M15 -> 0
A17: MARZO | G17: =ROUND(E17*F17,0) -> 0 | H17: 0 | I17: 0 | J17: 0 | K17: 0 | L17: 0 | M17: =G17+H17+I17+J17-K17-L17 -> 0 | N17: 0 | O17: 0
A18: MARZO | G18: =E18*F18 -> 0 | H18: 0 | I18: 0 | J18: 0 | K18: 0 | L18: 0 | M18: =G18+H18+I18+J18-K18-L18 -> 0 | O18: =H18+I18+J18+K18-L18-M18 -> 0
A19: MARZO | G19: =E19*F19 -> 0 | H19: 0 | I19: 0 | J19: 0 | K19: 0 | L19: 0 | M19: =G19+H19+I19+J19-K19-L19 -> 0 | O19: =H19+I19+J19+K19-L19-M19 -> 0
A20: MARZO | G20: =E20*F20 -> 0 | H20: 0 | I20: 0 | J20: 0 | K20: 0 | L20: 0 | M20: =G20+H20+I20+J20-K20-L20 -> 0 | O20: =H20+I20+J20+K20-L20-M20 -> 0
A23: ABRIL | G23: =ROUND(E23*F23,0) -> 0 | H23: 0 | I23: 0 | J23: 0 | K23: 0 | L23: 0 | M23: =G23+H23+I23+J23-K23-L23 -> 0 | N23: 0 | O23: 0
A24: ABRIL | G24: =E24*F24 -> 0 | H24: 0 | I24: 0 | J24: 0 | K24: 0 | L24: 0 | M24: =G24+H24+I24+J24-K24-L24 -> 0 | O24: =H24+I24+J24+K24-L24-M24 -> 0
A25: ABRIL | G25: =E25*F25 -> 0 | H25: 0 | I25: 0 | J25: 0 | K25: 0 | L25: 0 | M25: =G25+H25+I25+J25-K25-L25 -> 0 | O25: =H25+I25+J25+K25-L25-M25 -> 0
A26: ABRIL | G26: =E26*F26 -> 0 | H26: 0 | I26: 0 | J26: 0 | K26: 0 | L26: 0 | M26: =G26+H26+I26+J26-K26-L26 -> 0 | O26: =H26+I26+J26+K26-L26-M26 -> 0
A27: ABRIL | G27: =E27*F27 -> 0 | H27: 0 | I27: 0 | J27: 0 | K27: 0 | L27: 0 | M27: =G27+H27+I27+J27-K27-L27 -> 0 | O27: =H27+I27+J27+K27-L27-M27 -> 0
A29: MAYO | G29: =ROUND(E29*F29,0) -> 0 | H29: 0 | I29: 0 | J29: 0 | K29: 0 | L29: 0 | M29: =G29+H29+I29+J29-K29-L29 -> 0 | N29: 0 | O29: 0
A30: MAYO | G30: =E30*F30 -> 0 | H30: 0 | I30: 0 | J30: 0 | K30: 0 | L30: 0 | M30: =G30+H30+I30+J30-K30-L30 -> 0 | O30: =H30+I30+J30+K30-L30-M30 -> 0
A31: MAYO | G31: =E31*F31 -> 0 | H31: 0 | I31: 0 | J31: 0 | K31: 0 | L31: 0 | M31: =G31+H31+I31+J31-K31-L31 -> 0 | O31: =H31+I31+J31+K31-L31-M31 -> 0
A32: MAYO | G32: =E32*F32 -> 0 | H32: 0 | I32: 0 | J32: 0 | K32: 0 | L32: 0 | M32: =G32+H32+I32+J32-K32-L32 -> 0 | O32: =H32+I32+J32+K32-L32-M32 -> 0
A33: MAYO | G33: =E33*F33 -> 0 | H33: 0 | I33: 0 | J33: 0 | K33: 0 | L33: 0 | M33: =G33+H33+I33+J33-K33-L33 -> 0 | O33: =H33+I33+J33+K33-L33-M33 -> 0
A35: JUNIO | G35: =ROUND(E35*F35,0) -> 0 | H35: 0 | I35: 0 | J35: 0 | K35: 0 | L35: 0 | M35: =G35+H35+I35+J35-K35-L35 -> 0 | N35: 0 | O35: 0
A36: JUNIO | G36: =E36*F36 -> 0 | H36: 0 | I36: 0 | J36: 0 | K36: 0 | L36: 0 | M36: =G36+H36+I36+J36-K36-L36 -> 0 | O36: =H36+I36+J36+K36-L36-M36 -> 0
A37: JUNIO | G37: =E37*F37 -> 0 | H37: 0 | I37: 0 | J37: 0 | K37: 0 | L37: 0 | M37: =G37+H37+I37+J37-K37-L37 -> 0 | O37: =H37+I37+J37+K37-L37-M37 -> 0
A38: JUNIO | G38: =E38*F38 -> 0 | H38: 0 | I38: 0 | J38: 0 | K38: 0 | L38: 0 | M38: =G38+H38+I38+J38-K38-L38 -> 0 | O38: =H38+I38+J38+K38-L38-M38 -> 0
A39: JUNIO | G39: =E39*F39 -> 0 | H39: 0 | I39: 0 | J39: 0 | K39: 0 | L39: 0 | M39: =G39+H39+I39+J39-K39-L39 -> 0 | O39: =H39+I39+J39+K39-L39-M39 -> 0
A41: JULIO | G41: =ROUND(E41*F41,0) -> 0 | H41: 0 | I41: 0 | J41: 0 | K41: 0 | L41: 0 | M41: =G41+H41+I41+J41-K41-L41 -> 0 | N41: 0 | O41: 0
A42: JULIO | G42: =E42*F42 -> 0 | H42: 0 | I42: 0 | J42: 0 | K42: 0 | L42: 0 | M42: =G42+H42+I42+J42-K42-L42 -> 0 | N42: 0 | O42: =H42+I42+J42+K42-L42-M42 -> 0
A43: JULIO | G43: =E43*F43 -> 0 | H43: 0 | I43: 0 | J43: 0 | K43: 0 | L43: 0 | M43: =G43+H43+I43+J43-K43-L43 -> 0 | N43: 0 | O43: =H43+I43+J43+K43-L43-M43 -> 0
A44: JULIO | G44: =E44*F44 -> 0 | H44: 0 | I44: 0 | J44: 0 | K44: 0 | L44: 0 | M44: =G44+H44+I44+J44-K44-L44 -> 0 | N44: 0 | O44: =H44+I44+J44+K44-L44-M44 -> 0
A45: JULIO | G45: =E45*F45 -> 0 | H45: 0 | I45: 0 | J45: 0 | K45: 0 | L45: 0 | M45: =G45+H45+I45+J45-K45-L45 -> 0 | N45: 0 | O45: =H45+I45+J45+K45-L45-M45 -> 0
A47: AGOSTO | G47: =ROUND(E47*F47,0) -> 0 | H47: 0 | I47: 0 | J47: 0 | K47: 0 | L47: 0 | M47: =G47+H47+I47+J47-K47-L47 -> 0 | N47: 0 | O47: 0
A48: AGOSTO | G48: =E48*F48 -> 0 | H48: 0 | I48: 0 | J48: 0 | K48: 0 | L48: 0 | M48: =G48+H48+I48+J48-K48-L48 -> 0 | N48: 0 | O48: =H48+I48+J48+K48-L48-M48 -> 0
A49: AGOSTO | G49: =E49*F49 -> 0 | H49: 0 | I49: 0 | J49: 0 | K49: 0 | L49: 0 | M49: =G49+H49+I49+J49-K49-L49 -> 0 | N49: 0 | O49: =H49+I49+J49+K49-L49-M49 -> 0
A50: AGOSTO | G50: =E50*F50 -> 0 | H50: 0 | I50: 0 | J50: 0 | K50: 0 | L50: 0 | M50: =G50+H50+I50+J50-K50-L50 -> 0 | N50: 0 | O50: =H50+I50+J50+K50-L50-M50 -> 0
...

Sheet RET ISN
A1: =+ISN!A1 -> 0
A2: Voucheo de Retención del Impuesto Sobre Nóminas 2026
A3: MES | B3: TIPO | C3: TIPO2 | D3: ESTADO | E3: TOTAL FACTURADO | F3: BASE | G3: TASA | H3: IMPUESTO CAUSADO | I3: ACTUALIZACIONES | J3: RECARGOS | K3: GASTOS DE EJECUCIÓN | L3: RETENCIONES ISN | M3: ISN A FAVOR | N3: CANTIDAD A PAGAR | O3: CANTIDAD PAGADA | P3: CANTIDAD A FAVOR | R3: NUMERO DE COLABORADORES | S3: FECHA DE PRESENTACIÓN | T3: FOLIO | U3: REFERENCIA PAGO: | V3: FECHA DE PAGO EN BANCO | W3: INSTITUCIÓN BANCARIA | X3: No. DE OPERACIÓN BANCO | Y3: FACTURADO | Z3: UUID
A5: ENERO | H5: =ROUND(F5*G5,0) -> 0 | I5: 0 | J5: 0 | K5: 0 | L5: 0 | M5: 0 | N5: =H5+I5+J5+K5-L5-M5 -> 0 | O5: 0 | P5: 0
A6: ENERO | H6: =F6*G6 -> 0 | I6: 0 | J6: 0 | K6: 0 | L6: 0 | M6: 0 | N6: =H6+I6+J6+K6-L6-M6 -> 0 | P6: =I6+J6+K6+L6-M6-N6 -> 0
A7: ENERO | H7: =F7*G7 -> 0 | I7: 0 | J7: 0 | K7: 0 | L7: 0 | M7: 0 | N7: =H7+I7+J7+K7-L7-M7 -> 0 | P7: =I7+J7+K7+L7-M7-N7 -> 0
A8: ENERO | H8: =F8*G8 -> 0 | I8: 0 | J8: 0 | K8: 0 | L8: 0 | M8: 0 | N8: =H8+I8+J8+K8-L8-M8 -> 0 | P8: =I8+J8+K8+L8-M8-N8 -> 0
A9: ENERO | H9: =F9*G9 -> 0 | I9: 0 | J9: 0 | K9: 0 | L9: 0 | M9: 0 | N9: =H9+I9+J9+K9-L9-M9 -> 0 | P9: =I9+J9+K9+L9-M9-N9 -> 0
A11: FEBRERO | H11: =ROUND(F11*G11,0) -> 0 | I11: 0 | J11: 0 | K11: 0 | L11: 0 | M11: 0 | N11: =H11+I11+J11+K11-L11-M11 -> 0 | O11: 0 | P11: 0
A12: FEBRERO | H12: =F12*G12 -> 0 | I12: 0 | J12: 0 | K12: 0 | L12: 0 | M12: 0 | N12: =H12+I12+J12+K12-L12-M12 -> 0 | P12: =I12+J12+K12+L12-M12-N12 -> 0
A13: FEBRERO | H13: =F13*G13 -> 0 | I13: 0 | J13: 0 | K13: 0 | L13: 0 | M13: 0 | N13: =H13+I13+J13+K13-L13-M13 -> 0 | P13: =I13+J13+K13+L13-M13-N13 -> 0
A14: FEBRERO | H14: =F14*G14 -> 0 | I14: 0 | J14: 0 | K14: 0 | L14: 0 | M14: 0 | N14: =H14+I14+J14+K14-L14-M14 -> 0 | P14: =I14+J14+K14+L14-M14-N14 -> 0
A15: FEBRERO | H15: =F15*G15 -> 0 | I15: 0 | J15: 0 | K15: 0 | L15: 0 | M15: 0 | N15: =H15+I15+J15+K15-L15-M15 -> 0 | P15: =I15+J15+K15+L15-M15-N15 -> 0
A17: MARZO | H17: =ROUND(F17*G17,0) -> 0 | I17: 0 | J17: 0 | K17: 0 | L17: 0 | M17: 0 | N17: =H17+I17+J17+K17-L17-M17 -> 0 | O17: 0 | P17: 0
A18: MARZO | H18: =F18*G18 -> 0 | I18: 0 | J18: 0 | K18: 0 | L18: 0 | M18: 0 | N18: =H18+I18+J18+K18-L18-M18 -> 0 | P18: =I18+J18+K18+L18-M18-N18 -> 0
A19: MARZO | H19: =F19*G19 -> 0 | I19: 0 | J19: 0 | K19: 0 | L19: 0 | M19: 0 | N19: =H19+I19+J19+K19-L19-M19 -> 0 | P19: =I19+J19+K19+L19-M19-N19 -> 0
A20: MARZO | H20: =F20*G20 -> 0 | I20: 0 | J20: 0 | K20: 0 | L20: 0 | M20: 0 | N20: =H20+I20+J20+K20-L20-M20 -> 0 | P20: =I20+J20+K20+L20-M20-N20 -> 0
A23: ABRIL | H23: =ROUND(F23*G23,0) -> 0 | I23: 0 | J23: 0 | K23: 0 | L23: 0 | M23: 0 | N23: =H23+I23+J23+K23-L23-M23 -> 0 | O23: 0 | P23: 0
A24: ABRIL | H24: =F24*G24 -> 0 | I24: 0 | J24: 0 | K24: 0 | L24: 0 | M24: 0 | N24: =H24+I24+J24+K24-L24-M24 -> 0 | P24: =I24+J24+K24+L24-M24-N24 -> 0
A25: ABRIL | H25: =F25*G25 -> 0 | I25: 0 | J25: 0 | K25: 0 | L25: 0 | M25: 0 | N25: =H25+I25+J25+K25-L25-M25 -> 0 | P25: =I25+J25+K25+L25-M25-N25 -> 0
A26: ABRIL | H26: =F26*G26 -> 0 | I26: 0 | J26: 0 | K26: 0 | L26: 0 | M26: 0 | N26: =H26+I26+J26+K26-L26-M26 -> 0 | P26: =I26+J26+K26+L26-M26-N26 -> 0
A27: ABRIL | H27: =F27*G27 -> 0 | I27: 0 | J27: 0 | K27: 0 | L27: 0 | M27: 0 | N27: =H27+I27+J27+K27-L27-M27 -> 0 | P27: =I27+J27+K27+L27-M27-N27 -> 0
A29: MAYO | H29: =ROUND(F29*G29,0) -> 0 | I29: 0 | J29: 0 | K29: 0 | L29: 0 | M29: 0 | N29: =H29+I29+J29+K29-L29-M29 -> 0 | O29: 0 | P29: 0
A30: MAYO | H30: =F30*G30 -> 0 | I30: 0 | J30: 0 | K30: 0 | L30: 0 | M30: 0 | N30: =H30+I30+J30+K30-L30-M30 -> 0 | P30: =I30+J30+K30+L30-M30-N30 -> 0
A31: MAYO | H31: =F31*G31 -> 0 | I31: 0 | J31: 0 | K31: 0 | L31: 0 | M31: 0 | N31: =H31+I31+J31+K31-L31-M31 -> 0 | P31: =I31+J31+K31+L31-M31-N31 -> 0
A32: MAYO | H32: =F32*G32 -> 0 | I32: 0 | J32: 0 | K32: 0 | L32: 0 | M32: 0 | N32: =H32+I32+J32+K32-L32-M32 -> 0 | P32: =I32+J32+K32+L32-M32-N32 -> 0
A33: MAYO | H33: =F33*G33 -> 0 | I33: 0 | J33: 0 | K33: 0 | L33: 0 | M33: 0 | N33: =H33+I33+J33+K33-L33-M33 -> 0 | P33: =I33+J33+K33+L33-M33-N33 -> 0
A35: JUNIO | H35: =ROUND(F35*G35,0) -> 0 | I35: 0 | J35: 0 | K35: 0 | L35: 0 | M35: 0 | N35: =H35+I35+J35+K35-L35-M35 -> 0 | O35: 0 | P35: 0
A36: JUNIO | H36: =F36*G36 -> 0 | I36: 0 | J36: 0 | K36: 0 | L36: 0 | M36: 0 | N36: =H36+I36+J36+K36-L36-M36 -> 0 | P36: =I36+J36+K36+L36-M36-N36 -> 0
A37: JUNIO | H37: =F37*G37 -> 0 | I37: 0 | J37: 0 | K37: 0 | L37: 0 | M37: 0 | N37: =H37+I37+J37+K37-L37-M37 -> 0 | P37: =I37+J37+K37+L37-M37-N37 -> 0
A38: JUNIO | H38: =F38*G38 -> 0 | I38: 0 | J38: 0 | K38: 0 | L38: 0 | M38: 0 | N38: =H38+I38+J38+K38-L38-M38 -> 0 | P38: =I38+J38+K38+L38-M38-N38 -> 0
A39: JUNIO | H39: =F39*G39 -> 0 | I39: 0 | J39: 0 | K39: 0 | L39: 0 | M39: 0 | N39: =H39+I39+J39+K39-L39-M39 -> 0 | P39: =I39+J39+K39+L39-M39-N39 -> 0
A41: JULIO | H41: =ROUND(F41*G41,0) -> 0 | I41: 0 | J41: 0 | K41: 0 | L41: 0 | M41: 0 | N41: =H41+I41+J41+K41-L41-M41 -> 0 | O41: 0 | P41: 0
A42: JULIO | H42: =F42*G42 -> 0 | I42: 0 | J42: 0 | K42: 0 | L42: 0 | M42: 0 | N42: =H42+I42+J42+K42-L42-M42 -> 0 | P42: =I42+J42+K42+L42-M42-N42 -> 0
A43: JULIO | H43: =F43*G43 -> 0 | I43: 0 | J43: 0 | K43: 0 | L43: 0 | M43: 0 | N43: =H43+I43+J43+K43-L43-M43 -> 0 | P43: =I43+J43+K43+L43-M43-N43 -> 0
A44: JULIO | H44: =F44*G44 -> 0 | I44: 0 | J44: 0 | K44: 0 | L44: 0 | M44: 0 | N44: =H44+I44+J44+K44-L44-M44 -> 0 | P44: =I44+J44+K44+L44-M44-N44 -> 0
A45: JULIO | H45: =F45*G45 -> 0 | I45: 0 | J45: 0 | K45: 0 | L45: 0 | M45: 0 | N45: =H45+I45+J45+K45-L45-M45 -> 0 | P45: =I45+J45+K45+L45-M45-N45 -> 0
A47: AGOSTO | H47: =ROUND(F47*G47,0) -> 0 | I47: 0 | J47: 0 | K47: 0 | L47: 0 | M47: 0 | N47: =H47+I47+J47+K47-L47-M47 -> 0 | O47: 0 | P47: 0
A48: AGOSTO | H48: =F48*G48 -> 0 | I48: 0 | J48: 0 | K48: 0 | L48: 0 | M48: 0 | N48: =H48+I48+J48+K48-L48-M48 -> 0 | O48: 0 | P48: =I48+J48+K48+L48-M48-N48 -> 0
A49: AGOSTO | H49: =F49*G49 -> 0 | I49: 0 | J49: 0 | K49: 0 | L49: 0 | M49: 0 | N49: =H49+I49+J49+K49-L49-M49 -> 0 | O49: 0 | P49: =I49+J49+K49+L49-M49-N49 -> 0
...

Sheet ISH
A1: =+ISN!A1 -> 0
A2: Voucheo de Impuesto Sobre Hospedaje 2026
A3: MES | B3: TIPO | C3: TIPO2 | D3: ESTADO | E3: BASE | F3: TASA | G3: IMPUESTO CAUSADO | H3: ACTUALIZACIONES | I3: RECARGOS | J3: GASTOS DE EJECUCIÓN | K3: RETENCIONES ISH | L3: ISH A FAVOR | M3: CANTIDAD A PAGAR | N3: CANTIDAD PAGADA | O3: CANTIDAD A FAVOR | Q3: FECHA DE PRESENTACIÓN | R3: FOLIO | S3: REFERENCIA PAGO: | T3: FECHA DE PAGO EN BANCO | U3: INSTITUCIÓN BANCARIA | V3: No. DE OPERACIÓN BANCO | W3: FACTURADO | X3: UUID
A5: ENERO | G5: =ROUND(E5*F5,0) -> 0 | H5: 0 | I5: 0 | J5: 0 | K5: 0 | L5: 0 | M5: =G5+H5+I5+J5-L5 -> 0 | N5: 0 | O5: 0
A6: ENERO | G6: =E6*F6 -> 0 | H6: 0 | I6: 0 | J6: 0 | K6: 0 | L6: 0 | M6: =G6+H6+I6+J6-L6 -> 0 | N6: =H6+I6+J6+L6-M6-O6 -> 0 | O6: =G6+H6+I6+J6-L6-M6 -> 0
A7: ENERO | G7: =E7*F7 -> 0 | H7: 0 | I7: 0 | J7: 0 | K7: 0 | L7: 0 | M7: =G7+H7+I7+J7-L7 -> 0 | N7: =H7+I7+J7+L7-M7-O7 -> 0 | O7: =G7+H7+I7+J7-L7-M7 -> 0
A8: ENERO | G8: =E8*F8 -> 0 | H8: 0 | I8: 0 | J8: 0 | K8: 0 | L8: 0 | M8: =G8+H8+I8+J8-L8 -> 0 | N8: =H8+I8+J8+L8-M8-O8 -> 0 | O8: =G8+H8+I8+J8-L8-M8 -> 0
A9: ENERO | G9: =E9*F9 -> 0 | H9: 0 | I9: 0 | J9: 0 | K9: 0 | L9: 0 | M9: =G9+H9+I9+J9-L9 -> 0 | N9: =H9+I9+J9+L9-M9-O9 -> 0 | O9: =G9+H9+I9+J9-L9-M9 -> 0
A11: FEBRERO | G11: =ROUND(E11*F11,0) -> 0 | H11: 0 | I11: 0 | J11: 0 | K11: 0 | L11: 0 | M11: =G11+H11+I11+J11-L11 -> 0 | N11: 0 | O11: 0
A12: FEBRERO | G12: =E12*F12 -> 0 | H12: 0 | I12: 0 | J12: 0 | K12: 0 | L12: 0 | M12: =G12+H12+I12+J12-L12 -> 0 | N12: =H12+I12+J12+L12-M12-O12 -> 0 | O12: =G12+H12+I12+J12-L12-M12 -> 0
A13: FEBRERO | G13: =E13*F13 -> 0 | H13: 0 | I13: 0 | J13: 0 | K13: 0 | L13: 0 | M13: =G13+H13+I13+J13-L13 -> 0 | N13: =H13+I13+J13+L13-M13-O13 -> 0 | O13: =G13+H13+I13+J13-L13-M13 -> 0
A14: FEBRERO | G14: =E14*F14 -> 0 | H14: 0 | I14: 0 | J14: 0 | K14: 0 | L14: 0 | M14: =G14+H14+I14+J14-L14 -> 0 | N14: =H14+I14+J14+L14-M14-O14 -> 0 | O14: =G14+H14+I14+J14-L14-M14 -> 0
A15: FEBRERO | G15: =E15*F15 -> 0 | H15: 0 | I15: 0 | J15: 0 | K15: 0 | L15: 0 | M15: =G15+H15+I15+J15-L15 -> 0 | N15: =H15+I15+J15+L15-M15-O15 -> 0 | O15: =G15+H15+I15+J15-L15-M15 -> 0
A17: MARZO | G17: =ROUND(E17*F17,0) -> 0 | H17: 0 | I17: 0 | J17: 0 | K17: 0 | L17: 0 | M17: =G17+H17+I17+J17-L17 -> 0 | N17: 0 | O17: 0
A18: MARZO | G18: =E18*F18 -> 0 | H18: 0 | I18: 0 | J18: 0 | K18: 0 | L18: 0 | M18: =G18+H18+I18+J18-L18 -> 0 | N18: =H18+I18+J18+L18-M18-O18 -> 0 | O18: =G18+H18+I18+J18-L18-M18 -> 0
A19: MARZO | G19: =E19*F19 -> 0 | H19: 0 | I19: 0 | J19: 0 | K19: 0 | L19: 0 | M19: =G19+H19+I19+J19-L19 -> 0 | N19: =H19+I19+J19+L19-M19-O19 -> 0 | O19: =G19+H19+I19+J19-L19-M19 -> 0
A20: MARZO | G20: =E20*F20 -> 0 | H20: 0 | I20: 0 | J20: 0 | K20: 0 | L20: 0 | M20: =G20+H20+I20+J20-L20 -> 0 | N20: =H20+I20+J20+L20-M20-O20 -> 0 | O20: =G20+H20+I20+J20-L20-M20 -> 0
A23: ABRIL | G23: =ROUND(E23*F23,0) -> 0 | H23: 0 | I23: 0 | J23: 0 | K23: 0 | L23: 0 | M23: =G23+H23+I23+J23-L23 -> 0 | N23: 0 | O23: 0
A24: ABRIL | G24: =E24*F24 -> 0 | H24: 0 | I24: 0 | J24: 0 | K24: 0 | L24: 0 | M24: =G24+H24+I24+J24-L24 -> 0 | N24: =H24+I24+J24+L24-M24-O24 -> 0 | O24: =G24+H24+I24+J24-L24-M24 -> 0
A25: ABRIL | G25: =E25*F25 -> 0 | H25: 0 | I25: 0 | J25: 0 | K25: 0 | L25: 0 | M25: =G25+H25+I25+J25-L25 -> 0 | N25: =H25+I25+J25+L25-M25-O25 -> 0 | O25: =G25+H25+I25+J25-L25-M25 -> 0
A26: ABRIL | G26: =E26*F26 -> 0 | H26: 0 | I26: 0 | J26: 0 | K26: 0 | L26: 0 | M26: =G26+H26+I26+J26-L26 -> 0 | N26: =H26+I26+J26+L26-M26-O26 -> 0 | O26: =G26+H26+I26+J26-L26-M26 -> 0
A27: ABRIL | G27: =E27*F27 -> 0 | H27: 0 | I27: 0 | J27: 0 | K27: 0 | L27: 0 | M27: =G27+H27+I27+J27-L27 -> 0 | N27: =H27+I27+J27+L27-M27-O27 -> 0 | O27: =G27+H27+I27+J27-L27-M27 -> 0
A29: MAYO | G29: =ROUND(E29*F29,0) -> 0 | H29: 0 | I29: 0 | J29: 0 | K29: 0 | L29: 0 | M29: =G29+H29+I29+J29-L29 -> 0 | N29: 0 | O29: 0
A30: MAYO | G30: =E30*F30 -> 0 | H30: 0 | I30: 0 | J30: 0 | K30: 0 | L30: 0 | M30: =G30+H30+I30+J30-L30 -> 0 | N30: =H30+I30+J30+L30-M30-O30 -> 0 | O30: =G30+H30+I30+J30-L30-M30 -> 0
A31: MAYO | G31: =E31*F31 -> 0 | H31: 0 | I31: 0 | J31: 0 | K31: 0 | L31: 0 | M31: =G31+H31+I31+J31-L31 -> 0 | N31: =H31+I31+J31+L31-M31-O31 -> 0 | O31: =G31+H31+I31+J31-L31-M31 -> 0
A32: MAYO | G32: =E32*F32 -> 0 | H32: 0 | I32: 0 | J32: 0 | K32: 0 | L32: 0 | M32: =G32+H32+I32+J32-L32 -> 0 | N32: =H32+I32+J32+L32-M32-O32 -> 0 | O32: =G32+H32+I32+J32-L32-M32 -> 0
A33: MAYO | G33: =E33*F33 -> 0 | H33: 0 | I33: 0 | J33: 0 | K33: 0 | L33: 0 | M33: =G33+H33+I33+J33-L33 -> 0 | N33: =H33+I33+J33+L33-M33-O33 -> 0 | O33: =G33+H33+I33+J33-L33-M33 -> 0
A35: JUNIO | G35: =ROUND(E35*F35,0) -> 0 | H35: 0 | I35: 0 | J35: 0 | K35: 0 | L35: 0 | M35: =G35+H35+I35+J35-L35 -> 0 | N35: 0 | O35: 0
A36: JUNIO | G36: =E36*F36 -> 0 | H36: 0 | I36: 0 | J36: 0 | K36: 0 | L36: 0 | M36: =G36+H36+I36+J36-L36 -> 0 | N36: =H36+I36+J36+L36-M36-O36 -> 0 | O36: =G36+H36+I36+J36-L36-M36 -> 0
A37: JUNIO | G37: =E37*F37 -> 0 | H37: 0 | I37: 0 | J37: 0 | K37: 0 | L37: 0 | M37: =G37+H37+I37+J37-L37 -> 0 | N37: =H37+I37+J37+L37-M37-O37 -> 0 | O37: =G37+H37+I37+J37-L37-M37 -> 0
A38: JUNIO | G38: =E38*F38 -> 0 | H38: 0 | I38: 0 | J38: 0 | K38: 0 | L38: 0 | M38: =G38+H38+I38+J38-L38 -> 0 | N38: =H38+I38+J38+L38-M38-O38 -> 0 | O38: =G38+H38+I38+J38-L38-M38 -> 0
A39: JUNIO | G39: =E39*F39 -> 0 | H39: 0 | I39: 0 | J39: 0 | K39: 0 | L39: 0 | M39: =G39+H39+I39+J39-L39 -> 0 | N39: =H39+I39+J39+L39-M39-O39 -> 0 | O39: =G39+H39+I39+J39-L39-M39 -> 0
A41: JULIO | G41: =ROUND(E41*F41,0) -> 0 | H41: 0 | I41: 0 | J41: 0 | K41: 0 | L41: 0 | M41: =G41+H41+I41+J41-L41 -> 0 | N41: 0 | O41: 0
A42: JULIO | G42: =E42*F42 -> 0 | H42: 0 | I42: 0 | J42: 0 | K42: 0 | L42: 0 | M42: =G42+H42+I42+J42-L42 -> 0 | N42: =H42+I42+J42+L42-M42-O42 -> 0 | O42: =G42+H42+I42+J42-L42-M42 -> 0
A43: JULIO | G43: =E43*F43 -> 0 | H43: 0 | I43: 0 | J43: 0 | K43: 0 | L43: 0 | M43: =G43+H43+I43+J43-L43 -> 0 | N43: =H43+I43+J43+L43-M43-O43 -> 0 | O43: =G43+H43+I43+J43-L43-M43 -> 0
A44: JULIO | G44: =E44*F44 -> 0 | H44: 0 | I44: 0 | J44: 0 | K44: 0 | L44: 0 | M44: =G44+H44+I44+J44-L44 -> 0 | N44: =H44+I44+J44+L44-M44-O44 -> 0 | O44: =G44+H44+I44+J44-L44-M44 -> 0
A45: JULIO | G45: =E45*F45 -> 0 | H45: 0 | I45: 0 | J45: 0 | K45: 0 | L45: 0 | M45: =G45+H45+I45+J45-L45 -> 0 | N45: =H45+I45+J45+L45-M45-O45 -> 0 | O45: =G45+H45+I45+J45-L45-M45 -> 0
A47: AGOSTO | G47: =ROUND(E47*F47,0) -> 0 | H47: 0 | I47: 0 | J47: 0 | K47: 0 | L47: 0 | M47: =G47+H47+I47+J47-L47 -> 0 | N47: 0 | O47: 0
A48: AGOSTO | G48: =E48*F48 -> 0 | H48: 0 | I48: 0 | J48: 0 | K48: 0 | L48: 0 | M48: =G48+H48+I48+J48-L48 -> 0 | N48: =H48+I48+J48+L48-M48-O48 -> 0 | O48: =G48+H48+I48+J48-L48-M48 -> 0
A49: AGOSTO | G49: =E49*F49 -> 0 | H49: 0 | I49: 0 | J49: 0 | K49: 0 | L49: 0 | M49: =G49+H49+I49+J49-L49 -> 0 | N49: =H49+I49+J49+L49-M49-O49 -> 0 | O49: =G49+H49+I49+J49-L49-M49 -> 0
...

Sheet RESUMEN
A1: =ISN!A1 -> 0
A2: RESUMEN DE IMPUESTOS ESTATALES 2026
A3: MES | B3: ISN | C3: ISH | D3: RET ISN | E3: TOTAL
A4: Enero | B4: =SUMIFS(ISN!$G:$G,ISN!$A:$A,$A4) -> 0 | C4: =SUMIFS(ISH!$G:$G,ISH!$A:$A,$A4) -> 0 | D4: =SUMIFS('RET ISN'!$H:$H,'RET ISN'!$A:$A,$A4) -> 0 | E4: =SUM(B4:D4) -> 0
A5: Febrero | B5: =SUMIFS(ISN!$G:$G,ISN!$A:$A,$A5) -> 0 | C5: =SUMIFS(ISH!$G:$G,ISH!$A:$A,$A5) -> 0 | D5: =SUMIFS('RET ISN'!$H:$H,'RET ISN'!$A:$A,$A5) -> 0 | E5: =SUM(B5:D5) -> 0
A6: Marzo | B6: =SUMIFS(ISN!$G:$G,ISN!$A:$A,$A6) -> 0 | C6: =SUMIFS(ISH!$G:$G,ISH!$A:$A,$A6) -> 0 | D6: =SUMIFS('RET ISN'!$H:$H,'RET ISN'!$A:$A,$A6) -> 0 | E6: =SUM(B6:D6) -> 0
A7: Abril | B7: =SUMIFS(ISN!$G:$G,ISN!$A:$A,$A7) -> 0 | C7: =SUMIFS(ISH!$G:$G,ISH!$A:$A,$A7) -> 0 | D7: =SUMIFS('RET ISN'!$H:$H,'RET ISN'!$A:$A,$A7) -> 0 | E7: =SUM(B7:D7) -> 0
A8: Mayo | B8: =SUMIFS(ISN!$G:$G,ISN!$A:$A,$A8) -> 0 | C8: =SUMIFS(ISH!$G:$G,ISH!$A:$A,$A8) -> 0 | D8: =SUMIFS('RET ISN'!$H:$H,'RET ISN'!$A:$A,$A8) -> 0 | E8: =SUM(B8:D8) -> 0
A9: Junio | B9: =SUMIFS(ISN!$G:$G,ISN!$A:$A,$A9) -> 0 | C9: =SUMIFS(ISH!$G:$G,ISH!$A:$A,$A9) -> 0 | D9: =SUMIFS('RET ISN'!$H:$H,'RET ISN'!$A:$A,$A9) -> 0 | E9: =SUM(B9:D9) -> 0
A10: Julio | B10: =SUMIFS(ISN!$G:$G,ISN!$A:$A,$A10) -> 0 | C10: =SUMIFS(ISH!$G:$G,ISH!$A:$A,$A10) -> 0 | D10: =SUMIFS('RET ISN'!$H:$H,'RET ISN'!$A:$A,$A10) -> 0 | E10: =SUM(B10:D10) -> 0
A11: Agosto | B11: =SUMIFS(ISN!$G:$G,ISN!$A:$A,$A11) -> 0 | C11: =SUMIFS(ISH!$G:$G,ISH!$A:$A,$A11) -> 0 | D11: =SUMIFS('RET ISN'!$H:$H,'RET ISN'!$A:$A,$A11) -> 0 | E11: =SUM(B11:D11) -> 0
A12: Septiembre | B12: =SUMIFS(ISN!$G:$G,ISN!$A:$A,$A12) -> 0 | C12: =SUMIFS(ISH!$G:$G,ISH!$A:$A,$A12) -> 0 | D12: =SUMIFS('RET ISN'!$H:$H,'RET ISN'!$A:$A,$A12) -> 0 | E12: =SUM(B12:D12) -> 0
A13: Octubre | B13: =SUMIFS(ISN!$G:$G,ISN!$A:$A,$A13) -> 0 | C13: =SUMIFS(ISH!$G:$G,ISH!$A:$A,$A13) -> 0 | D13: =SUMIFS('RET ISN'!$H:$H,'RET ISN'!$A:$A,$A13) -> 0 | E13: =SUM(B13:D13) -> 0
A14: Noviembre | B14: =SUMIFS(ISN!$G:$G,ISN!$A:$A,$A14) -> 0 | C14: =SUMIFS(ISH!$G:$G,ISH!$A:$A,$A14) -> 0 | D14: =SUMIFS('RET ISN'!$H:$H,'RET ISN'!$A:$A,$A14) -> 0 | E14: =SUM(B14:D14) -> 0
A15: Diciembre | B15: =SUMIFS(ISN!$G:$G,ISN!$A:$A,$A15) -> 0 | C15: =SUMIFS(ISH!$G:$G,ISH!$A:$A,$A15) -> 0 | D15: =SUMIFS('RET ISN'!$H:$H,'RET ISN'!$A:$A,$A15) -> 0 | E15: =SUM(B15:D15) -> 0
B17: =SUM(B4:B16) -> 0 | C17: =SUM(C4:C16) -> 0 | D17: =SUM(D4:D16) -> 0 | E17: =SUM(E4:E16) -> 0

Sheet VAR
A1: Tipo de declaración | C1: Complementaria | E1: Normal | G1: DIOT
A2: Normal | C2: Dejar Sin Efecto Obligación | E2: Normal | G2: Normal
A3: Complementaria | C3: Modificación de Obligaciones | G3: Complementaria
A4: Normal por Correción Fiscal | C4: Obligación no presentada
A5: Complementaria Correción Fiscal | C5: Esquema anterior
A6: Complementaria Dictamen | C6: Dictamen Auditoría
A7: Complementaria Esquema Anterior
A11: t_TipoDeclaración | C11: t_Complementaria | E11: t_Normal
